Workbook

Sheet Dashboard
A1: 📊 CAPITALO Economy — Dashboard
A2: Kluczowe metryki ekonomii. Jeśli liczby tu wyglądają OK, gra będzie miała dobry pacing.
A4: 🎯 KEY MILESTONES
A5: Milestone | B5: Hour reached | C5: Cumulative $ | D5: Status | E5: Goal
A6: Tech unlock ($1k) | B6: =IFERROR(MATCH(TRUE(),INDEX(Progression!F5:F64>=1000,0),0),"60+ h") -> 3 | C6: 1000 | D6: ✓ check Progression sheet | E6: h <= 5
A7: Food unlock ($50k) | B7: =IFERROR(MATCH(TRUE(),INDEX(Progression!F5:F64>=50000,0),0),"60+ h") -> 17 | C7: 50000 | D7: ✓ check Progression sheet | E7: h <= 30
A8: Home unlock ($1M) | B8: =IFERROR(MATCH(TRUE(),INDEX(Progression!F5:F64>=1000000,0),0),"60+ h") -> 31 | C8: 1000000 | D8: ✓ check Progression sheet | E8: h <= 45
A9: Beauty unlock ($50M) | B9: =IFERROR(MATCH(TRUE(),INDEX(Progression!F5:F64>=50000000,0),0),"60+ h") -> 48 | C9: 50000000 | D9: ✓ check Progression sheet | E9: h <= 55
A10: First prestige ($1B) | B10: =IFERROR(MATCH(TRUE(),INDEX(Progression!F5:F64>=1000000000,0),0),"60+ h") -> 60+ h | C10: 1000000000 | D10: ✓ check Progression sheet | E10: h ≈ 60-65
A12: 📈 PROGRESSION SUMMARY
A13: Total earned @ 60h | B13: =Progression!F64 -> 7.9934862e+08 | C13: Powinno być blisko 1B dla prestige
A14: Income/sec @ 60h | B14: =Progression!D64 -> 228385.66 | C14: Wysokie = gracz już generuje sporo
A15: Hourly earnings @ 60h | B15: =Progression!E64 -> 1.5986996e+08 | C15: Per godzina gameplay
A16: Categories unlocked @ 60h | B16: =Progression!G64 -> 5 | C16: Powinno być 4-6 z 10
A18: 🔄 PRESTIGE METRICS
A19: IP gained from 1st prestige | B19: =Prestige_Loop!C5 -> 1 | C19: Powinno być 1-3 IP - słaba ale satysfakcjonująca pierwsza nagroda
A20: IP gained from 5th prestige | B20: =Prestige_Loop!C9 -> 9 | C20: Tu krzywa zaczyna naprawdę rosnąć
A21: Total IP po 10 prestiżach | B21: =Prestige_Loop!D14 -> 328 | C21: Sumarycznie do tego momentu
A22: Multiplier po 10 prestiżach | B22: =Prestige_Loop!E14 -> 656 | C22: % bonus do income permanent
A23: Total godzin do 10 prestiżu | B23: =SUM(Prestige_Loop!F5:F14) -> 426.81274 | C23: Suma godzin gameplay
A25: 🔧 TUNING GUIDE
A26: 💡 Jeśli pierwszy prestige < 40h: zwiększ prestige_base_threshold (Parameters!B26) lub zmniejsz hourly_growth_rate (Parameters!B42)
A27: 💡 Jeśli pierwszy prestige > 80h: zmniejsz prestige_base_threshold lub zwiększ hourly_growth_rate
A28: 💡 Jeśli kategorie odblokowują się za szybko: zwiększ unlock_cost w Shop_Categories (kolumna D)
A29: 💡 Jeśli kategorie nie odblokowują się: zmniejsz unlock_cost
A30: 💡 Jeśli upgrade'y są za drogie: zmniejsz shop_level_cost_growth do 1.13 (Parameters!B7)
A31: 💡 Jeśli upgrade'y są za tanie: zwiększ shop_level_cost_growth do 1.17
A32: 💡 Po 5 prestiżach gracz powinien czuć 'znaczący' boost — sprawdź multiplier @ 5 w Prestige_Loop

Sheet Parameters
A1: CAPITALO — Economy Parameters
A2: Edytuj wartości w żółtych komórkach. Pozostałe arkusze przeliczają się automatycznie.
A4: CORE ECONOMY
A5: Parameter | B5: Value | C5: Unit | D5: Notes
A6: starting_money | B6: 50 | C6: $ | D6: Kasa na start gry
A7: shop_level_cost_growth | B7: 1.15 | C7: x | D7: Koszt N+1 levelu = N * X. AdVenture Capitalist używa 1.15
A8: shop_income_growth | B8: 1.07 | C8: x | D8: Income N+1 levelu = N * X
A9: category_base_multiplier | B9: 5.6 | C9: x | D9: Każda kolejna kategoria sklepów ma X razy większy base income
A10: manager_base_multiplier | B10: 2 | C10: x | D10: Manager od razu daje x2 income
A11: manager_level_bonus | B11: 0.1 | C11: % | D11: +X% za każdy level managera (1-10)
A12: brand_rep_neutral | B12: 3 | C12: stars | D12: Neutralna reputacja
A13: rep_per_star_bonus | B13: 0.1 | C13: % | D13: +X% income per gwiazdka powyżej neutral
A15: MARKETING CAMPAIGNS
A16: Campaign | B16: Cost ($) | C16: Cooldown (s) | D16: Success % | E16: Viral % | F16: Customers Min | G16: Customers Max | H16: Unlocks at
A17: Flyers | B17: 5 | C17: 2 | D17: 80 | E17: 1 | F17: 5 | G17: 10 | H17: Start
A18: Facebook Ads | B18: 50 | C18: 5 | D18: 70 | E18: 5 | F18: 30 | G18: 80 | H18: $1k earned
A19: Google Ads | B19: 80 | C19: 5 | D19: 75 | E19: 3 | F19: 40 | G19: 100 | H19: Tech: Targeting
A20: Influencer | B20: 500 | C20: 30 | D20: 60 | E20: 15 | F20: 200 | G20: 2000 | H20: $50k earned
A21: TV Spot | B21: 5000 | C21: 120 | D21: 90 | E21: 8 | F21: 1000 | G21: 5000 | H21: $1M earned
A22: TikTok Viral | B22: 200 | C22: 60 | D22: 40 | E22: 25 | F22: 50 | G22: 50000 | H22: Tech: Viral Studio II
A23: Super Bowl Ad | B23: 10000000 | C23: 3600 | D23: 95 | E23: 30 | F23: 100000 | G23: 500000 | H23: Endgame
A25: PRESTIGE & META
A26: Parameter | B26: Value | C26: Unit | D26: Notes
A27: prestige_base_threshold | B27: 1000000000 | C27: $ | D27: Total earned dla 1 IP
A28: prestige_exponent | B28: 0.5 | C28: exp | D28: Wykładnik krzywej IP. 0.5 = sqrt
A29: prestige_multiplier_per_ip | B29: 0.02 | C29: % | D29: +X% income permanent per IP
A30: offline_cap_hours | B30: 8 | C30: h | D30: Max godzin offline earnings
A31: offline_efficiency | B31: 0.5 | C31: % | D31: X% online rate gdy offline
A32: offline_ad_boost | B32: 2 | C32: x | D32: Watch ad → x2 offline earnings
A34: PLAYER BEHAVIOR ASSUMPTIONS
A35: Parameter | B35: Value | C35: Unit | D35: Notes
A36: clicks_per_minute_active | B36: 15 | C36: clicks/min | D36: Aktywne klikanie kampanii na minutę
A37: active_session_minutes | B37: 10 | C37: min | D37: Średnia długość aktywnej sesji
A38: sessions_per_day | B38: 4 | C38: /day | D38: Ile razy gracz odpala grę dziennie
A39: offline_hours_avg | B39: 6 | C39: h | D39: Średnio ile godzin między sesjami
A40: upgrade_efficiency | B40: 0.7 | C40: % | D40: Jak optymalnie gracz wydaje kasę (1.0 = perfect)
A41: avg_campaign_revenue_multiplier | B41: 1.5 | C41: x | D41: Średnia mnożnika przychodu z kampanii (success/viral/fail)
A42: hourly_growth_rate | B42: 1.25 | C42: x | D42: Wzrost income/sec na godzinę aktywnej gry. WAŻNE - reguluje tempo

Sheet Shop_Categories
A1: Shop Categories — Base Income Skalowanie
A2: Każda kategoria ma base income = poprzednia * category_base_multiplier (z Parameters).
A4: Order | B4: Category | C4: Base Income ($/sec) | D4: Unlock Cost ($) | E4: Phase | F4: Notes
A5: 1 | B5: Fashion | C5: 1 | D5: 0 | E5: Phase 1 (MVP) | F5: Kategoria startowa
A6: 2 | B6: Tech | C6: =C5*Parameters!$B$9 -> 5.6 | D6: 1000 | E6: Phase 1 (MVP) | F6: Elektronika, gadżety
A7: 3 | B7: Food | C7: =C6*Parameters!$B$9 -> 31.36 | D7: 50000 | E7: Phase 1 (MVP) | F7: Restauracje, fast food
A8: 4 | B8: Home | C8: =C7*Parameters!$B$9 -> 175.616 | D8: 1000000 | E8: Phase 2 | F8: Meble, dekoracje
A9: 5 | B9: Beauty | C9: =C8*Parameters!$B$9 -> 983.4496 | D9: 50000000 | E9: Phase 2 | F9: Kosmetyki, perfumy
A10: 6 | B10: Books & Media | C10: =C9*Parameters!$B$9 -> 5507.3178 | D10: 1000000000 | E10: Phase 2 | F10: Książki, vinyle
A11: 7 | B11: Toys | C11: =C10*Parameters!$B$9 -> 30840.979 | D11: 100000000000 | E11: Phase 2 | F11: Zabawki, kolekcjonerskie
A12: 8 | B12: Sports | C12: =C11*Parameters!$B$9 -> 172709.48 | D12: 10000000000000 | E12: Phase 2 | F12: Sprzęt sportowy
A13: 9 | B13: Luxury | C13: =C12*Parameters!$B$9 -> 967173.12 | D13: 1e+15 | E13: Phase 3 | F13: Jubiler, designer goods
A14: 10 | B14: Marketplace | C14: =C13*Parameters!$B$9 -> 5416169.4 | D14: 1e+17 | E14: Phase 3 | F14: Endgame: meta-poziom
A17: LEVEL CURVE — Fashion (Category 1)
A18: Pokazuje jak rośnie koszt i income z każdym levelem (Fashion shop, base = 1.0 $/sec)
A19: Level | B19: Level Cost ($) | C19: Income/sec ($) | D19: Income/sec with Manager | E19: Cost/Income Ratio (s) | F19: Cumulative Cost
A20: 1 | B20: =10*POWER(Parameters!$B$7,0) -> 10 | C20: =$C$5*POWER(Parameters!$B$8,1) -> 1.07 | D20: =C20*Parameters!$B$10 -> 2.14 | E20: =B20/D20 -> 4.6728972 | F20: =B20 -> 10
A21: 2 | B21: =10*POWER(Parameters!$B$7,1) -> 11.5 | C21: =$C$5*POWER(Parameters!$B$8,2) -> 1.1449 | D21: =C21*Parameters!$B$10 -> 2.2898 | E21: =B21/D21 -> 5.0222727 | F21: =F20+B21 -> 21.5
A22: 3 | B22: =10*POWER(Parameters!$B$7,2) -> 13.225 | C22: =$C$5*POWER(Parameters!$B$8,3) -> 1.225043 | D22: =C22*Parameters!$B$10 -> 2.450086 | E22: =B22/D22 -> 5.3977697 | F22: =F21+B22 -> 34.725
A23: 4 | B23: =10*POWER(Parameters!$B$7,3) -> 15.20875 | C23: =$C$5*POWER(Parameters!$B$8,4) -> 1.310796 | D23: =C23*Parameters!$B$10 -> 2.621592 | E23: =B23/D23 -> 5.8013413 | F23: =F22+B23 -> 49.93375
A24: 5 | B24: =10*POWER(Parameters!$B$7,4) -> 17.490063 | C24: =$C$5*POWER(Parameters!$B$8,5) -> 1.4025517 | D24: =C24*Parameters!$B$10 -> 2.8051035 | E24: =B24/D24 -> 6.2350864 | F24: =F23+B24 -> 67.423812
A25: 6 | B25: =10*POWER(Parameters!$B$7,5) -> 20.113572 | C25: =$C$5*POWER(Parameters!$B$8,6) -> 1.5007304 | D25: =C25*Parameters!$B$10 -> 3.0014607 | E25: =B25/D25 -> 6.7012611 | F25: =F24+B25 -> 87.537384
A26: 7 | B26: =10*POWER(Parameters!$B$7,6) -> 23.130608 | C26: =$C$5*POWER(Parameters!$B$8,7) -> 1.6057815 | D26: =C26*Parameters!$B$10 -> 3.211563 | E26: =B26/D26 -> 7.20229 | F26: =F25+B26 -> 110.66799
A27: 8 | B27: =10*POWER(Parameters!$B$7,7) -> 26.600199 | C27: =$C$5*POWER(Parameters!$B$8,8) -> 1.7181862 | D27: =C27*Parameters!$B$10 -> 3.4363724 | E27: =B27/D27 -> 7.7407789 | F27: =F26+B27 -> 137.26819
A28: 9 | B28: =10*POWER(Parameters!$B$7,8) -> 30.590229 | C28: =$C$5*POWER(Parameters!$B$8,9) -> 1.8384592 | D28: =C28*Parameters!$B$10 -> 3.6769184 | E28: =B28/D28 -> 8.3195288 | F28: =F27+B28 -> 167.85842
A29: 10 | B29: =10*POWER(Parameters!$B$7,9) -> 35.178763 | C29: =$C$5*POWER(Parameters!$B$8,10) -> 1.9671514 | D29: =C29*Parameters!$B$10 -> 3.9343027 | E29: =B29/D29 -> 8.9415496 | F29: =F28+B29 -> 203.03718
A30: 11 | B30: =10*POWER(Parameters!$B$7,10) -> 40.455577 | C30: =$C$5*POWER(Parameters!$B$8,11) -> 2.104852 | D30: =C30*Parameters!$B$10 -> 4.2097039 | E30: =B30/D30 -> 9.6100767 | F30: =F29+B30 -> 243.49276
A31: 12 | B31: =10*POWER(Parameters!$B$7,11) -> 46.523914 | C31: =$C$5*POWER(Parameters!$B$8,12) -> 2.2521916 | D31: =C31*Parameters!$B$10 -> 4.5043832 | E31: =B31/D31 -> 10.328587 | F31: =F30+B31 -> 290.01667
A32: 13 | B32: =10*POWER(Parameters!$B$7,12) -> 53.502501 | C32: =$C$5*POWER(Parameters!$B$8,13) -> 2.409845 | D32: =C32*Parameters!$B$10 -> 4.81969 | E32: =B32/D32 -> 11.100818 | F32: =F31+B32 -> 343.51917
A33: 14 | B33: =10*POWER(Parameters!$B$7,13) -> 61.527876 | C33: =$C$5*POWER(Parameters!$B$8,14) -> 2.5785342 | D33: =C33*Parameters!$B$10 -> 5.1570683 | E33: =B33/D33 -> 11.930786 | F33: =F32+B33 -> 405.04705
A34: 15 | B34: =10*POWER(Parameters!$B$7,14) -> 70.757058 | C34: =$C$5*POWER(Parameters!$B$8,15) -> 2.7590315 | D34: =C34*Parameters!$B$10 -> 5.5180631 | E34: =B34/D34 -> 12.822807 | F34: =F33+B34 -> 475.80411
A35: 16 | B35: =10*POWER(Parameters!$B$7,15) -> 81.370616 | C35: =$C$5*POWER(Parameters!$B$8,16) -> 2.9521637 | D35: =C35*Parameters!$B$10 -> 5.9043275 | E35: =B35/D35 -> 13.781521 | F35: =F34+B35 -> 557.17472
A36: 17 | B36: =10*POWER(Parameters!$B$7,16) -> 93.576209 | C36: =$C$5*POWER(Parameters!$B$8,17) -> 3.1588152 | D36: =C36*Parameters!$B$10 -> 6.3176304 | E36: =B36/D36 -> 14.811916 | F36: =F35+B36 -> 650.75093
A37: 18 | B37: =10*POWER(Parameters!$B$7,17) -> 107.61264 | C37: =$C$5*POWER(Parameters!$B$8,18) -> 3.3799323 | D37: =C37*Parameters!$B$10 -> 6.7598646 | E37: =B37/D37 -> 15.919349 | F37: =F36+B37 -> 758.36357
A38: 19 | B38: =10*POWER(Parameters!$B$7,18) -> 123.75454 | C38: =$C$5*POWER(Parameters!$B$8,19) -> 3.6165275 | D38: =C38*Parameters!$B$10 -> 7.2330551 | E38: =B38/D38 -> 17.10958 | F38: =F37+B38 -> 882.11811
A39: 20 | B39: =10*POWER(Parameters!$B$7,19) -> 142.31772 | C39: =$C$5*POWER(Parameters!$B$8,20) -> 3.8696845 | D39: =C39*Parameters!$B$10 -> 7.7393689 | E39: =B39/D39 -> 18.388801 | F39: =F38+B39 -> 1024.4358
A40: 21 | B40: =10*POWER(Parameters!$B$7,20) -> 163.66537 | C40: =$C$5*POWER(Parameters!$B$8,21) -> 4.1405624 | D40: =C40*Parameters!$B$10 -> 8.2811247 | E40: =B40/D40 -> 19.763665 | F40: =F39+B40 -> 1188.1012
A41: 22 | B41: =10*POWER(Parameters!$B$7,21) -> 188.21518 | C41: =$C$5*POWER(Parameters!$B$8,22) -> 4.4304017 | D41: =C41*Parameters!$B$10 -> 8.8608035 | E41: =B41/D41 -> 21.241322 | F41: =F40+B41 -> 1376.3164
A42: 23 | B42: =10*POWER(Parameters!$B$7,22) -> 216.44746 | C42: =$C$5*POWER(Parameters!$B$8,23) -> 4.7405299 | D42: =C42*Parameters!$B$10 -> 9.4810597 | E42: =B42/D42 -> 22.829458 | F42: =F41+B42 -> 1592.7638
A43: 24 | B43: =10*POWER(Parameters!$B$7,23) -> 248.91458 | C43: =$C$5*POWER(Parameters!$B$8,24) -> 5.072367 | D43: =C43*Parameters!$B$10 -> 10.144734 | E43: =B43/D43 -> 24.536334 | F43: =F42+B43 -> 1841.6784
...

Sheet Progression
A1: Capitalo — Progression Curve (60h gameplay)
A2: Symulacja przychodu i progressu godzina po godzinie. Edytuj 'hourly_growth_rate' w Parameters aby strojaść tempo.
A4: Hour | B4: Active Min | C4: Offline Min | D4: Income/sec (avg) | E4: Hourly Earnings ($) | F4: Cumulative Total ($) | G4: Categories Unlocked | H4: Phase
A5: 1 | B5: =Parameters!$B$37*(Parameters!$B$38/24) -> 1.6666667 | C5: =MIN(60-B5,Parameters!$B$30*60/24) -> 20 | D5: =0.5*POWER(Parameters!$B$42,1)*Parameters!$B$40 -> 0.4375 | E5: =D5*(B5*60 + C5*60*Parameters!$B$31) -> 306.25 | F5: =E5+Parameters!$B$6 -> 356.25 | G5: =IF(F5>=Shop_Categories!$D$14,10,IF(F5>=Shop_Categories!$D$13,9,IF(F5>=Shop_Categories!$D$12,8,IF(F5>=Shop_Categories!$D$11,7,IF(F5>=Shop_Categories!$D$10,6,IF(F5>=Shop_Categories!$D$9,5,IF(F5>=Shop_Categories!$D$8,4,IF(F5>=Shop_Categories!$D$7,3,IF(F5>=Shop_Categories!$D$6,2,1))))))))) -> 1 | H5: Onboarding
A6: 2 | B6: =Parameters!$B$37*(Parameters!$B$38/24) -> 1.6666667 | C6: =MIN(60-B6,Parameters!$B$30*60/24) -> 20 | D6: =0.5*POWER(Parameters!$B$42,2)*Parameters!$B$40 -> 0.546875 | E6: =D6*(B6*60 + C6*60*Parameters!$B$31) -> 382.8125 | F6: =F5+E6 -> 739.0625 | G6: =IF(F6>=Shop_Categories!$D$14,10,IF(F6>=Shop_Categories!$D$13,9,IF(F6>=Shop_Categories!$D$12,8,IF(F6>=Shop_Categories!$D$11,7,IF(F6>=Shop_Categories!$D$10,6,IF(F6>=Shop_Categories!$D$9,5,IF(F6>=Shop_Categories!$D$8,4,IF(F6>=Shop_Categories!$D$7,3,IF(F6>=Shop_Categories!$D$6,2,1))))))))) -> 1 | H6: Onboarding
A7: 3 | B7: =Parameters!$B$37*(Parameters!$B$38/24) -> 1.6666667 | C7: =MIN(60-B7,Parameters!$B$30*60/24) -> 20 | D7: =0.5*POWER(Parameters!$B$42,3)*Parameters!$B$40 -> 0.68359375 | E7: =D7*(B7*60 + C7*60*Parameters!$B$31) -> 478.51562 | F7: =F6+E7 -> 1217.5781 | G7: =IF(F7>=Shop_Categories!$D$14,10,IF(F7>=Shop_Categories!$D$13,9,IF(F7>=Shop_Categories!$D$12,8,IF(F7>=Shop_Categories!$D$11,7,IF(F7>=Shop_Categories!$D$10,6,IF(F7>=Shop_Categories!$D$9,5,IF(F7>=Shop_Categories!$D$8,4,IF(F7>=Shop_Categories!$D$7,3,IF(F7>=Shop_Categories!$D$6,2,1))))))))) -> 2 | H7: Onboarding
A8: 4 | B8: =Parameters!$B$37*(Parameters!$B$38/24) -> 1.6666667 | C8: =MIN(60-B8,Parameters!$B$30*60/24) -> 20 | D8: =0.5*POWER(Parameters!$B$42,4)*Parameters!$B$40 -> 0.85449219 | E8: =D8*(B8*60 + C8*60*Parameters!$B$31) -> 598.14453 | F8: =F7+E8 -> 1815.7227 | G8: =IF(F8>=Shop_Categories!$D$14,10,IF(F8>=Shop_Categories!$D$13,9,IF(F8>=Shop_Categories!$D$12,8,IF(F8>=Shop_Categories!$D$11,7,IF(F8>=Shop_Categories!$D$10,6,IF(F8>=Shop_Categories!$D$9,5,IF(F8>=Shop_Categories!$D$8,4,IF(F8>=Shop_Categories!$D$7,3,IF(F8>=Shop_Categories!$D$6,2,1))))))))) -> 2 | H8: Onboarding
A9: 5 | B9: =Parameters!$B$37*(Parameters!$B$38/24) -> 1.6666667 | C9: =MIN(60-B9,Parameters!$B$30*60/24) -> 20 | D9: =0.5*POWER(Parameters!$B$42,5)*Parameters!$B$40 -> 1.0681152 | E9: =D9*(B9*60 + C9*60*Parameters!$B$31) -> 747.68066 | F9: =F8+E9 -> 2563.4033 | G9: =IF(F9>=Shop_Categories!$D$14,10,IF(F9>=Shop_Categories!$D$13,9,IF(F9>=Shop_Categories!$D$12,8,IF(F9>=Shop_Categories!$D$11,7,IF(F9>=Shop_Categories!$D$10,6,IF(F9>=Shop_Categories!$D$9,5,IF(F9>=Shop_Categories!$D$8,4,IF(F9>=Shop_Categories!$D$7,3,IF(F9>=Shop_Categories!$D$6,2,1))))))))) -> 2 | H9: Onboarding
A10: 6 | B10: =Parameters!$B$37*(Parameters!$B$38/24) -> 1.6666667 | C10: =MIN(60-B10,Parameters!$B$30*60/24) -> 20 | D10: =0.5*POWER(Parameters!$B$42,6)*Parameters!$B$40 -> 1.335144 | E10: =D10*(B10*60 + C10*60*Parameters!$B$31) -> 934.60083 | F10: =F9+E10 -> 3498.0042 | G10: =IF(F10>=Shop_Categories!$D$14,10,IF(F10>=Shop_Categories!$D$13,9,IF(F10>=Shop_Categories!$D$12,8,IF(F10>=Shop_Categories!$D$11,7,IF(F10>=Shop_Categories!$D$10,6,IF(F10>=Shop_Categories!$D$9,5,IF(F10>=Shop_Categories!$D$8,4,IF(F10>=Shop_Categories!$D$7,3,IF(F10>=Shop_Categories!$D$6,2,1))))))))) -> 2 | H10: Early Game
A11: 7 | B11: =Parameters!$B$37*(Parameters!$B$38/24) -> 1.6666667 | C11: =MIN(60-B11,Parameters!$B$30*60/24) -> 20 | D11: =0.5*POWER(Parameters!$B$42,7)*Parameters!$B$40 -> 1.6689301 | E11: =D11*(B11*60 + C11*60*Parameters!$B$31) -> 1168.251 | F11: =F10+E11 -> 4666.2552 | G11: =IF(F11>=Shop_Categories!$D$14,10,IF(F11>=Shop_Categories!$D$13,9,IF(F11>=Shop_Categories!$D$12,8,IF(F11>=Shop_Categories!$D$11,7,IF(F11>=Shop_Categories!$D$10,6,IF(F11>=Shop_Categories!$D$9,5,IF(F11>=Shop_Categories!$D$8,4,IF(F11>=Shop_Categories!$D$7,3,IF(F11>=Shop_Categories!$D$6,2,1))))))))) -> 2 | H11: Early Game
A12: 8 | B12: =Parameters!$B$37*(Parameters!$B$38/24) -> 1.6666667 | C12: =MIN(60-B12,Parameters!$B$30*60/24) -> 20 | D12: =0.5*POWER(Parameters!$B$42,8)*Parameters!$B$40 -> 2.0861626 | E12: =D12*(B12*60 + C12*60*Parameters!$B$31) -> 1460.3138 | F12: =F11+E12 -> 6126.569 | G12: =IF(F12>=Shop_Categories!$D$14,10,IF(F12>=Shop_Categories!$D$13,9,IF(F12>=Shop_Categories!$D$12,8,IF(F12>=Shop_Categories!$D$11,7,IF(F12>=Shop_Categories!$D$10,6,IF(F12>=Shop_Categories!$D$9,5,IF(F12>=Shop_Categories!$D$8,4,IF(F12>=Shop_Categories!$D$7,3,IF(F12>=Shop_Categories!$D$6,2,1))))))))) -> 2 | H12: Early Game
A13: 9 | B13: =Parameters!$B$37*(Parameters!$B$38/24) -> 1.6666667 | C13: =MIN(60-B13,Parameters!$B$30*60/24) -> 20 | D13: =0.5*POWER(Parameters!$B$42,9)*Parameters!$B$40 -> 2.6077032 | E13: =D13*(B13*60 + C13*60*Parameters!$B$31) -> 1825.3922 | F13: =F12+E13 -> 7951.9612 | G13: =IF(F13>=Shop_Categories!$D$14,10,IF(F13>=Shop_Categories!$D$13,9,IF(F13>=Shop_Categories!$D$12,8,IF(F13>=Shop_Categories!$D$11,7,IF(F13>=Shop_Categories!$D$10,6,IF(F13>=Shop_Categories!$D$9,5,IF(F13>=Shop_Categories!$D$8,4,IF(F13>=Shop_Categories!$D$7,3,IF(F13>=Shop_Categories!$D$6,2,1))))))))) -> 2 | H13: Early Game
A14: 10 | B14: =Parameters!$B$37*(Parameters!$B$38/24) -> 1.6666667 | C14: =MIN(60-B14,Parameters!$B$30*60/24) -> 20 | D14: =0.5*POWER(Parameters!$B$42,10)*Parameters!$B$40 -> 3.259629 | E14: =D14*(B14*60 + C14*60*Parameters!$B$31) -> 2281.7403 | F14: =F13+E14 -> 10233.702 | G14: =IF(F14>=Shop_Categories!$D$14,10,IF(F14>=Shop_Categories!$D$13,9,IF(F14>=Shop_Categories!$D$12,8,IF(F14>=Shop_Categories!$D$11,7,IF(F14>=Shop_Categories!$D$10,6,IF(F14>=Shop_Categories!$D$9,5,IF(F14>=Shop_Categories!$D$8,4,IF(F14>=Shop_Categories!$D$7,3,IF(F14>=Shop_Categories!$D$6,2,1))))))))) -> 2 | H14: Early Game
A15: 11 | B15: =Parameters!$B$37*(Parameters!$B$38/24) -> 1.6666667 | C15: =MIN(60-B15,Parameters!$B$30*60/24) -> 20 | D15: =0.5*POWER(Parameters!$B$42,11)*Parameters!$B$40 -> 4.0745363 | E15: =D15*(B15*60 + C15*60*Parameters!$B$31) -> 2852.1754 | F15: =F14+E15 -> 13085.877 | G15: =IF(F15>=Shop_Categories!$D$14,10,IF(F15>=Shop_Categories!$D$13,9,IF(F15>=Shop_Categories!$D$12,8,IF(F15>=Shop_Categories!$D$11,7,IF(F15>=Shop_Categories!$D$10,6,IF(F15>=Shop_Categories!$D$9,5,IF(F15>=Shop_Categories!$D$8,4,IF(F15>=Shop_Categories!$D$7,3,IF(F15>=Shop_Categories!$D$6,2,1))))))))) -> 2 | H15: Early Game
A16: 12 | B16: =Parameters!$B$37*(Parameters!$B$38/24) -> 1.6666667 | C16: =MIN(60-B16,Parameters!$B$30*60/24) -> 20 | D16: =0.5*POWER(Parameters!$B$42,12)*Parameters!$B$40 -> 5.0931703 | E16: =D16*(B16*60 + C16*60*Parameters!$B$31) -> 3565.2192 | F16: =F15+E16 -> 16651.096 | G16: =IF(F16>=Shop_Categories!$D$14,10,IF(F16>=Shop_Categories!$D$13,9,IF(F16>=Shop_Categories!$D$12,8,IF(F16>=Shop_Categories!$D$11,7,IF(F16>=Shop_Categories!$D$10,6,IF(F16>=Shop_Categories!$D$9,5,IF(F16>=Shop_Categories!$D$8,4,IF(F16>=Shop_Categories!$D$7,3,IF(F16>=Shop_Categories!$D$6,2,1))))))))) -> 2 | H16: Early Game
A17: 13 | B17: =Parameters!$B$37*(Parameters!$B$38/24) -> 1.6666667 | C17: =MIN(60-B17,Parameters!$B$30*60/24) -> 20 | D17: =0.5*POWER(Parameters!$B$42,13)*Parameters!$B$40 -> 6.3664629 | E17: =D17*(B17*60 + C17*60*Parameters!$B$31) -> 4456.524 | F17: =F16+E17 -> 21107.62 | G17: =IF(F17>=Shop_Categories!$D$14,10,IF(F17>=Shop_Categories!$D$13,9,IF(F17>=Shop_Categories!$D$12,8,IF(F17>=Shop_Categories!$D$11,7,IF(F17>=Shop_Categories!$D$10,6,IF(F17>=Shop_Categories!$D$9,5,IF(F17>=Shop_Categories!$D$8,4,IF(F17>=Shop_Categories!$D$7,3,IF(F17>=Shop_Categories!$D$6,2,1))))))))) -> 2 | H17: Early Game
A18: 14 | B18: =Parameters!$B$37*(Parameters!$B$38/24) -> 1.6666667 | C18: =MIN(60-B18,Parameters!$B$30*60/24) -> 20 | D18: =0.5*POWER(Parameters!$B$42,14)*Parameters!$B$40 -> 7.9580786 | E18: =D18*(B18*60 + C18*60*Parameters!$B$31) -> 5570.655 | F18: =F17+E18 -> 26678.275 | G18: =IF(F18>=Shop_Categories!$D$14,10,IF(F18>=Shop_Categories!$D$13,9,IF(F18>=Shop_Categories!$D$12,8,IF(F18>=Shop_Categories!$D$11,7,IF(F18>=Shop_Categories!$D$10,6,IF(F18>=Shop_Categories!$D$9,5,IF(F18>=Shop_Categories!$D$8,4,IF(F18>=Shop_Categories!$D$7,3,IF(F18>=Shop_Categories!$D$6,2,1))))))))) -> 2 | H18: Early Game
A19: 15 | B19: =Parameters!$B$37*(Parameters!$B$38/24) -> 1.6666667 | C19: =MIN(60-B19,Parameters!$B$30*60/24) -> 20 | D19: =0.5*POWER(Parameters!$B$42,15)*Parameters!$B$40 -> 9.9475983 | E19: =D19*(B19*60 + C19*60*Parameters!$B$31) -> 6963.3188 | F19: =F18+E19 -> 33641.594 | G19: =IF(F19>=Shop_Categories!$D$14,10,IF(F19>=Shop_Categories!$D$13,9,IF(F19>=Shop_Categories!$D$12,8,IF(F19>=Shop_Categories!$D$11,7,IF(F19>=Shop_Categories!$D$10,6,IF(F19>=Shop_Categories!$D$9,5,IF(F19>=Shop_Categories!$D$8,4,IF(F19>=Shop_Categories!$D$7,3,IF(F19>=Shop_Categories!$D$6,2,1))))))))) -> 2 | H19: Early Game
A20: 16 | B20: =Parameters!$B$37*(Parameters!$B$38/24) -> 1.6666667 | C20: =MIN(60-B20,Parameters!$B$30*60/24) -> 20 | D20: =0.5*POWER(Parameters!$B$42,16)*Parameters!$B$40 -> 12.434498 | E20: =D20*(B20*60 + C20*60*Parameters!$B$31) -> 8704.1485 | F20: =F19+E20 -> 42345.743 | G20: =IF(F20>=Shop_Categories!$D$14,10,IF(F20>=Shop_Categories!$D$13,9,IF(F20>=Shop_Categories!$D$12,8,IF(F20>=Shop_Categories!$D$11,7,IF(F20>=Shop_Categories!$D$10,6,IF(F20>=Shop_Categories!$D$9,5,IF(F20>=Shop_Categories!$D$8,4,IF(F20>=Shop_Categories!$D$7,3,IF(F20>=Shop_Categories!$D$6,2,1))))))))) -> 2 | H20: Mid Game
A21: 17 | B21: =Parameters!$B$37*(Parameters!$B$38/24) -> 1.6666667 | C21: =MIN(60-B21,Parameters!$B$30*60/24) -> 20 | D21: =0.5*POWER(Parameters!$B$42,17)*Parameters!$B$40 -> 15.543122 | E21: =D21*(B21*60 + C21*60*Parameters!$B$31) -> 10880.186 | F21: =F20+E21 -> 53225.928 | G21: =IF(F21>=Shop_Categories!$D$14,10,IF(F21>=Shop_Categories!$D$13,9,IF(F21>=Shop_Categories!$D$12,8,IF(F21>=Shop_Categories!$D$11,7,IF(F21>=Shop_Categories!$D$10,6,IF(F21>=Shop_Categories!$D$9,5,IF(F21>=Shop_Categories!$D$8,4,IF(F21>=Shop_Categories!$D$7,3,IF(F21>=Shop_Categories!$D$6,2,1))))))))) -> 3 | H21: Mid Game
A22: 18 | B22: =Parameters!$B$37*(Parameters!$B$38/24) -> 1.6666667 | C22: =MIN(60-B22,Parameters!$B$30*60/24) -> 20 | D22: =0.5*POWER(Parameters!$B$42,18)*Parameters!$B$40 -> 19.428903 | E22: =D22*(B22*60 + C22*60*Parameters!$B$31) -> 13600.232 | F22: =F21+E22 -> 66826.16 | G22: =IF(F22>=Shop_Categories!$D$14,10,IF(F22>=Shop_Categories!$D$13,9,IF(F22>=Shop_Categories!$D$12,8,IF(F22>=Shop_Categories!$D$11,7,IF(F22>=Shop_Categories!$D$10,6,IF(F22>=Shop_Categories!$D$9,5,IF(F22>=Shop_Categories!$D$8,4,IF(F22>=Shop_Categories!$D$7,3,IF(F22>=Shop_Categories!$D$6,2,1))))))))) -> 3 | H22: Mid Game
A23: 19 | B23: =Parameters!$B$37*(Parameters!$B$38/24) -> 1.6666667 | C23: =MIN(60-B23,Parameters!$B$30*60/24) -> 20 | D23: =0.5*POWER(Parameters!$B$42,19)*Parameters!$B$40 -> 24.286129 | E23: =D23*(B23*60 + C23*60*Parameters!$B$31) -> 17000.29 | F23: =F22+E23 -> 83826.45 | G23: =IF(F23>=Shop_Categories!$D$14,10,IF(F23>=Shop_Categories!$D$13,9,IF(F23>=Shop_Categories!$D$12,8,IF(F23>=Shop_Categories!$D$11,7,IF(F23>=Shop_Categories!$D$10,6,IF(F23>=Shop_Categories!$D$9,5,IF(F23>=Shop_Categories!$D$8,4,IF(F23>=Shop_Categories!$D$7,3,IF(F23>=Shop_Categories!$D$6,2,1))))))))) -> 3 | H23: Mid Game
A24: 20 | B24: =Parameters!$B$37*(Parameters!$B$38/24) -> 1.6666667 | C24: =MIN(60-B24,Parameters!$B$30*60/24) -> 20 | D24: =0.5*POWER(Parameters!$B$42,20)*Parameters!$B$40 -> 30.357661 | E24: =D24*(B24*60 + C24*60*Parameters!$B$31) -> 21250.363 | F24: =F23+E24 -> 105076.81 | G24: =IF(F24>=Shop_Categories!$D$14,10,IF(F24>=Shop_Categories!$D$13,9,IF(F24>=Shop_Categories!$D$12,8,IF(F24>=Shop_Categories!$D$11,7,IF(F24>=Shop_Categories!$D$10,6,IF(F24>=Shop_Categories!$D$9,5,IF(F24>=Shop_Categories!$D$8,4,IF(F24>=Shop_Categories!$D$7,3,IF(F24>=Shop_Categories!$D$6,2,1))))))))) -> 3 | H24: Mid Game
A25: 21 | B25: =Parameters!$B$37*(Parameters!$B$38/24) -> 1.6666667 | C25: =MIN(60-B25,Parameters!$B$30*60/24) -> 20 | D25: =0.5*POWER(Parameters!$B$42,21)*Parameters!$B$40 -> 37.947076 | E25: =D25*(B25*60 + C25*60*Parameters!$B$31) -> 26562.953 | F25: =F24+E25 -> 131639.77 | G25: =IF(F25>=Shop_Categories!$D$14,10,IF(F25>=Shop_Categories!$D$13,9,IF(F25>=Shop_Categories!$D$12,8,IF(F25>=Shop_Categories!$D$11,7,IF(F25>=Shop_Categories!$D$10,6,IF(F25>=Shop_Categories!$D$9,5,IF(F25>=Shop_Categories!$D$8,4,IF(F25>=Shop_Categories!$D$7,3,IF(F25>=Shop_Categories!$D$6,2,1))))))))) -> 3 | H25: Mid Game
A26: 22 | B26: =Parameters!$B$37*(Parameters!$B$38/24) -> 1.6666667 | C26: =MIN(60-B26,Parameters!$B$30*60/24) -> 20 | D26: =0.5*POWER(Parameters!$B$42,22)*Parameters!$B$40 -> 47.433845 | E26: =D26*(B26*60 + C26*60*Parameters!$B$31) -> 33203.692 | F26: =F25+E26 -> 164843.46 | G26: =IF(F26>=Shop_Categories!$D$14,10,IF(F26>=Shop_Categories!$D$13,9,IF(F26>=Shop_Categories!$D$12,8,IF(F26>=Shop_Categories!$D$11,7,IF(F26>=Shop_Categories!$D$10,6,IF(F26>=Shop_Categories!$D$9,5,IF(F26>=Shop_Categories!$D$8,4,IF(F26>=Shop_Categories!$D$7,3,IF(F26>=Shop_Categories!$D$6,2,1))))))))) -> 3 | H26: Mid Game
A27: 23 | B27: =Parameters!$B$37*(Parameters!$B$38/24) -> 1.6666667 | C27: =MIN(60-B27,Parameters!$B$30*60/24) -> 20 | D27: =0.5*POWER(Parameters!$B$42,23)*Parameters!$B$40 -> 59.292306 | E27: =D27*(B27*60 + C27*60*Parameters!$B$31) -> 41504.614 | F27: =F26+E27 -> 206348.07 | G27: =IF(F27>=Shop_Categories!$D$14,10,IF(F27>=Shop_Categories!$D$13,9,IF(F27>=Shop_Categories!$D$12,8,IF(F27>=Shop_Categories!$D$11,7,IF(F27>=Shop_Categories!$D$10,6,IF(F27>=Shop_Categories!$D$9,5,IF(F27>=Shop_Categories!$D$8,4,IF(F27>=Shop_Categories!$D$7,3,IF(F27>=Shop_Categories!$D$6,2,1))))))))) -> 3 | H27: Mid Game
A28: 24 | B28: =Parameters!$B$37*(Parameters!$B$38/24) -> 1.6666667 | C28: =MIN(60-B28,Parameters!$B$30*60/24) -> 20 | D28: =0.5*POWER(Parameters!$B$42,24)*Parameters!$B$40 -> 74.115383 | E28: =D28*(B28*60 + C28*60*Parameters!$B$31) -> 51880.768 | F28: =F27+E28 -> 258228.84 | G28: =IF(F28>=Shop_Categories!$D$14,10,IF(F28>=Shop_Categories!$D$13,9,IF(F28>=Shop_Categories!$D$12,8,IF(F28>=Shop_Categories!$D$11,7,IF(F28>=Shop_Categories!$D$10,6,IF(F28>=Shop_Categories!$D$9,5,IF(F28>=Shop_Categories!$D$8,4,IF(F28>=Shop_Categories!$D$7,3,IF(F28>=Shop_Categories!$D$6,2,1))))))))) -> 3 | H28: Mid Game
A29: 25 | B29: =Parameters!$B$37*(Parameters!$B$38/24) -> 1.6666667 | C29: =MIN(60-B29,Parameters!$B$30*60/24) -> 20 | D29: =0.5*POWER(Parameters!$B$42,25)*Parameters!$B$40 -> 92.644229 | E29: =D29*(B29*60 + C29*60*Parameters!$B$31) -> 64850.96 | F29: =F28+E29 -> 323079.8 | G29: =IF(F29>=Shop_Categories!$D$14,10,IF(F29>=Shop_Categories!$D$13,9,IF(F29>=Shop_Categories!$D$12,8,IF(F29>=Shop_Categories!$D$11,7,IF(F29>=Shop_Categories!$D$10,6,IF(F29>=Shop_Categories!$D$9,5,IF(F29>=Shop_Categories!$D$8,4,IF(F29>=Shop_Categories!$D$7,3,IF(F29>=Shop_Categories!$D$6,2,1))))))))) -> 3 | H29: Mid Game
A30: 26 | B30: =Parameters!$B$37*(Parameters!$B$38/24) -> 1.6666667 | C30: =MIN(60-B30,Parameters!$B$30*60/24) -> 20 | D30: =0.5*POWER(Parameters!$B$42,26)*Parameters!$B$40 -> 115.80529 | E30: =D30*(B30*60 + C30*60*Parameters!$B$31) -> 81063.7 | F30: =F29+E30 -> 404143.5 | G30: =IF(F30>=Shop_Categories!$D$14,10,IF(F30>=Shop_Categories!$D$13,9,IF(F30>=Shop_Categories!$D$12,8,IF(F30>=Shop_Categories!$D$11,7,IF(F30>=Shop_Categories!$D$10,6,IF(F30>=Shop_Categories!$D$9,5,IF(F30>=Shop_Categories!$D$8,4,IF(F30>=Shop_Categories!$D$7,3,IF(F30>=Shop_Categories!$D$6,2,1))))))))) -> 3 | H30: Mid Game
A31: 27 | B31: =Parameters!$B$37*(Parameters!$B$38/24) -> 1.6666667 | C31: =MIN(60-B31,Parameters!$B$30*60/24) -> 20 | D31: =0.5*POWER(Parameters!$B$42,27)*Parameters!$B$40 -> 144.75661 | E31: =D31*(B31*60 + C31*60*Parameters!$B$31) -> 101329.63 | F31: =F30+E31 -> 505473.13 | G31: =IF(F31>=Shop_Categories!$D$14,10,IF(F31>=Shop_Categories!$D$13,9,IF(F31>=Shop_Categories!$D$12,8,IF(F31>=Shop_Categories!$D$11,7,IF(F31>=Shop_Categories!$D$10,6,IF(F31>=Shop_Categories!$D$9,5,IF(F31>=Shop_Categories!$D$8,4,IF(F31>=Shop_Categories!$D$7,3,IF(F31>=Shop_Categories!$D$6,2,1))))))))) -> 3 | H31: Mid Game
A32: 28 | B32: =Parameters!$B$37*(Parameters!$B$38/24) -> 1.6666667 | C32: =MIN(60-B32,Parameters!$B$30*60/24) -> 20 | D32: =0.5*POWER(Parameters!$B$42,28)*Parameters!$B$40 -> 180.94576 | E32: =D32*(B32*60 + C32*60*Parameters!$B$31) -> 126662.03 | F32: =F31+E32 -> 632135.16 | G32: =IF(F32>=Shop_Categories!$D$14,10,IF(F32>=Shop_Categories!$D$13,9,IF(F32>=Shop_Categories!$D$12,8,IF(F32>=Shop_Categories!$D$11,7,IF(F32>=Shop_Categories!$D$10,6,IF(F32>=Shop_Categories!$D$9,5,IF(F32>=Shop_Categories!$D$8,4,IF(F32>=Shop_Categories!$D$7,3,IF(F32>=Shop_Categories!$D$6,2,1))))))))) -> 3 | H32: Mid Game
A33: 29 | B33: =Parameters!$B$37*(Parameters!$B$38/24) -> 1.6666667 | C33: =MIN(60-B33,Parameters!$B$30*60/24) -> 20 | D33: =0.5*POWER(Parameters!$B$42,29)*Parameters!$B$40 -> 226.1822 | E33: =D33*(B33*60 + C33*60*Parameters!$B$31) -> 158327.54 | F33: =F32+E33 -> 790462.7 | G33: =IF(F33>=Shop_Categories!$D$14,10,IF(F33>=Shop_Categories!$D$13,9,IF(F33>=Shop_Categories!$D$12,8,IF(F33>=Shop_Categories!$D$11,7,IF(F33>=Shop_Categories!$D$10,6,IF(F33>=Shop_Categories!$D$9,5,IF(F33>=Shop_Categories!$D$8,4,IF(F33>=Shop_Categories!$D$7,3,IF(F33>=Shop_Categories!$D$6,2,1))))))))) -> 3 | H33: Mid Game
A34: 30 | B34: =Parameters!$B$37*(Parameters!$B$38/24) -> 1.6666667 | C34: =MIN(60-B34,Parameters!$B$30*60/24) -> 20 | D34: =0.5*POWER(Parameters!$B$42,30)*Parameters!$B$40 -> 282.72775 | E34: =D34*(B34*60 + C34*60*Parameters!$B$31) -> 197909.42 | F34: =F33+E34 -> 988372.12 | G34: =IF(F34>=Shop_Categories!$D$14,10,IF(F34>=Shop_Categories!$D$13,9,IF(F34>=Shop_Categories!$D$12,8,IF(F34>=Shop_Categories!$D$11,7,IF(F34>=Shop_Categories!$D$10,6,IF(F34>=Shop_Categories!$D$9,5,IF(F34>=Shop_Categories!$D$8,4,IF(F34>=Shop_Categories!$D$7,3,IF(F34>=Shop_Categories!$D$6,2,1))))))))) -> 3 | H34: Mid Game
A35: 31 | B35: =Parameters!$B$37*(Parameters!$B$38/24) -> 1.6666667 | C35: =MIN(60-B35,Parameters!$B$30*60/24) -> 20 | D35: =0.5*POWER(Parameters!$B$42,31)*Parameters!$B$40 -> 353.40969 | E35: =D35*(B35*60 + C35*60*Parameters!$B$31) -> 247386.78 | F35: =F34+E35 -> 1235758.9 | G35: =IF(F35>=Shop_Categories!$D$14,10,IF(F35>=Shop_Categories!$D$13,9,IF(F35>=Shop_Categories!$D$12,8,IF(F35>=Shop_Categories!$D$11,7,IF(F35>=Shop_Categories!$D$10,6,IF(F35>=Shop_Categories!$D$9,5,IF(F35>=Shop_Categories!$D$8,4,IF(F35>=Shop_Categories!$D$7,3,IF(F35>=Shop_Categories!$D$6,2,1))))))))) -> 4 | H35: Mid Game
A36: 32 | B36: =Parameters!$B$37*(Parameters!$B$38/24) -> 1.6666667 | C36: =MIN(60-B36,Parameters!$B$30*60/24) -> 20 | D36: =0.5*POWER(Parameters!$B$42,32)*Parameters!$B$40 -> 441.76211 | E36: =D36*(B36*60 + C36*60*Parameters!$B$31) -> 309233.47 | F36: =F35+E36 -> 1544992.4 | G36: =IF(F36>=Shop_Categories!$D$14,10,IF(F36>=Shop_Categories!$D$13,9,IF(F36>=Shop_Categories!$D$12,8,IF(F36>=Shop_Categories!$D$11,7,IF(F36>=Shop_Categories!$D$10,6,IF(F36>=Shop_Categories!$D$9,5,IF(F36>=Shop_Categories!$D$8,4,IF(F36>=Shop_Categories!$D$7,3,IF(F36>=Shop_Categories!$D$6,2,1))))))))) -> 4 | H36: Mid Game
A37: 33 | B37: =Parameters!$B$37*(Parameters!$B$38/24) -> 1.6666667 | C37: =MIN(60-B37,Parameters!$B$30*60/24) -> 20 | D37: =0.5*POWER(Parameters!$B$42,33)*Parameters!$B$40 -> 552.20263 | E37: =D37*(B37*60 + C37*60*Parameters!$B$31) -> 386541.84 | F37: =F36+E37 -> 1931534.2 | G37: =IF(F37>=Shop_Categories!$D$14,10,IF(F37>=Shop_Categories!$D$13,9,IF(F37>=Shop_Categories!$D$12,8,IF(F37>=Shop_Categories!$D$11,7,IF(F37>=Shop_Categories!$D$10,6,IF(F37>=Shop_Categories!$D$9,5,IF(F37>=Shop_Categories!$D$8,4,IF(F37>=Shop_Categories!$D$7,3,IF(F37>=Shop_Categories!$D$6,2,1))))))))) -> 4 | H37: Mid Game
A38: 34 | B38: =Parameters!$B$37*(Parameters!$B$38/24) -> 1.6666667 | C38: =MIN(60-B38,Parameters!$B$30*60/24) -> 20 | D38: =0.5*POWER(Parameters!$B$42,34)*Parameters!$B$40 -> 690.25329 | E38: =D38*(B38*60 + C38*60*Parameters!$B$31) -> 483177.3 | F38: =F37+E38 -> 2414711.5 | G38: =IF(F38>=Shop_Categories!$D$14,10,IF(F38>=Shop_Categories!$D$13,9,IF(F38>=Shop_Categories!$D$12,8,IF(F38>=Shop_Categories!$D$11,7,IF(F38>=Shop_Categories!$D$10,6,IF(F38>=Shop_Categories!$D$9,5,IF(F38>=Shop_Categories!$D$8,4,IF(F38>=Shop_Categories!$D$7,3,IF(F38>=Shop_Categories!$D$6,2,1))))))))) -> 4 | H38: Mid Game
A39: 35 | B39: =Parameters!$B$37*(Parameters!$B$38/24) -> 1.6666667 | C39: =MIN(60-B39,Parameters!$B$30*60/24) -> 20 | D39: =0.5*POWER(Parameters!$B$42,35)*Parameters!$B$40 -> 862.81662 | E39: =D39*(B39*60 + C39*60*Parameters!$B$31) -> 603971.63 | F39: =F38+E39 -> 3018683.2 | G39: =IF(F39>=Shop_Categories!$D$14,10,IF(F39>=Shop_Categories!$D$13,9,IF(F39>=Shop_Categories!$D$12,8,IF(F39>=Shop_Categories!$D$11,7,IF(F39>=Shop_Categories!$D$10,6,IF(F39>=Shop_Categories!$D$9,5,IF(F39>=Shop_Categories!$D$8,4,IF(F39>=Shop_Categories!$D$7,3,IF(F39>=Shop_Categories!$D$6,2,1))))))))) -> 4 | H39: Mid Game
A40: 36 | B40: =Parameters!$B$37*(Parameters!$B$38/24) -> 1.6666667 | C40: =MIN(60-B40,Parameters!$B$30*60/24) -> 20 | D40: =0.5*POWER(Parameters!$B$42,36)*Parameters!$B$40 -> 1078.5208 | E40: =D40*(B40*60 + C40*60*Parameters!$B$31) -> 754964.54 | F40: =F39+E40 -> 3773647.7 | G40: =IF(F40>=Shop_Categories!$D$14,10,IF(F40>=Shop_Categories!$D$13,9,IF(F40>=Shop_Categories!$D$12,8,IF(F40>=Shop_Categories!$D$11,7,IF(F40>=Shop_Categories!$D$10,6,IF(F40>=Shop_Categories!$D$9,5,IF(F40>=Shop_Categories!$D$8,4,IF(F40>=Shop_Categories!$D$7,3,IF(F40>=Shop_Categories!$D$6,2,1))))))))) -> 4 | H40: Late Game
A41: 37 | B41: =Parameters!$B$37*(Parameters!$B$38/24) -> 1.6666667 | C41: =MIN(60-B41,Parameters!$B$30*60/24) -> 20 | D41: =0.5*POWER(Parameters!$B$42,37)*Parameters!$B$40 -> 1348.151 | E41: =D41*(B41*60 + C41*60*Parameters!$B$31) -> 943705.67 | F41: =F40+E41 -> 4717353.4 | G41: =IF(F41>=Shop_Categories!$D$14,10,IF(F41>=Shop_Categories!$D$13,9,IF(F41>=Shop_Categories!$D$12,8,IF(F41>=Shop_Categories!$D$11,7,IF(F41>=Shop_Categories!$D$10,6,IF(F41>=Shop_Categories!$D$9,5,IF(F41>=Shop_Categories!$D$8,4,IF(F41>=Shop_Categories!$D$7,3,IF(F41>=Shop_Categories!$D$6,2,1))))))))) -> 4 | H41: Late Game
...

Sheet Prestige_Loop
A1: Prestige Loop — Innovation Points & Multipliers
A2: Pokazuje jak skaluje się prestige cycle. Zakładamy że każdy kolejny prestige osiągany przy ~3x większej kasie.
A4: Prestige # | B4: Total Earned ($) | C4: IP Gained This Prestige | D4: IP Cumulative | E4: Multiplier Active (%) | F4: Hours to Next Prestige (est)
A5: 1 | B5: =Parameters!$B$27 -> 1000000000 | C5: =FLOOR(POWER(B5/Parameters!$B$27,Parameters!$B$28),1) -> 1 | D5: =C5 -> 1 | E5: =D5*Parameters!$B$29*100 -> 2 | F5: 60
A6: 2 | B6: =B5*3 -> 3000000000 | C6: =FLOOR(POWER(B6/Parameters!$B$27,Parameters!$B$28),1) -> 1 | D6: =D5+C6 -> 2 | E6: =D6*Parameters!$B$29*100 -> 4 | F6: =60/(1+D6*Parameters!$B$29*0.5) -> 58.823529
A7: 3 | B7: =B6*3 -> 9000000000 | C7: =FLOOR(POWER(B7/Parameters!$B$27,Parameters!$B$28),1) -> 3 | D7: =D6+C7 -> 5 | E7: =D7*Parameters!$B$29*100 -> 10 | F7: =60/(1+D7*Parameters!$B$29*0.5) -> 57.142857
A8: 4 | B8: =B7*3 -> 27000000000 | C8: =FLOOR(POWER(B8/Parameters!$B$27,Parameters!$B$28),1) -> 5 | D8: =D7+C8 -> 10 | E8: =D8*Parameters!$B$29*100 -> 20 | F8: =60/(1+D8*Parameters!$B$29*0.5) -> 54.545455
A9: 5 | B9: =B8*3 -> 81000000000 | C9: =FLOOR(POWER(B9/Parameters!$B$27,Parameters!$B$28),1) -> 9 | D9: =D8+C9 -> 19 | E9: =D9*Parameters!$B$29*100 -> 38 | F9: =60/(1+D9*Parameters!$B$29*0.5) -> 50.420168
A10: 6 | B10: =B9*3 -> 243000000000 | C10: =FLOOR(POWER(B10/Parameters!$B$27,Parameters!$B$28),1) -> 15 | D10: =D9+C10 -> 34 | E10: =D10*Parameters!$B$29*100 -> 68 | F10: =60/(1+D10*Parameters!$B$29*0.5) -> 44.776119
A11: 7 | B11: =B10*3 -> 729000000000 | C11: =FLOOR(POWER(B11/Parameters!$B$27,Parameters!$B$28),1) -> 27 | D11: =D10+C11 -> 61 | E11: =D11*Parameters!$B$29*100 -> 122 | F11: =60/(1+D11*Parameters!$B$29*0.5) -> 37.267081
A12: 8 | B12: =B11*3 -> 2187000000000 | C12: =FLOOR(POWER(B12/Parameters!$B$27,Parameters!$B$28),1) -> 46 | D12: =D11+C12 -> 107 | E12: =D12*Parameters!$B$29*100 -> 214 | F12: =60/(1+D12*Parameters!$B$29*0.5) -> 28.985507
A13: 9 | B13: =B12*3 -> 6561000000000 | C13: =FLOOR(POWER(B13/Parameters!$B$27,Parameters!$B$28),1) -> 81 | D13: =D12+C13 -> 188 | E13: =D13*Parameters!$B$29*100 -> 376 | F13: =60/(1+D13*Parameters!$B$29*0.5) -> 20.833333
A14: 10 | B14: =B13*3 -> 19683000000000 | C14: =FLOOR(POWER(B14/Parameters!$B$27,Parameters!$B$28),1) -> 140 | D14: =D13+C14 -> 328 | E14: =D14*Parameters!$B$29*100 -> 656 | F14: =60/(1+D14*Parameters!$B$29*0.5) -> 14.018692
A15: 11 | B15: =B14*3 -> 59049000000000 | C15: =FLOOR(POWER(B15/Parameters!$B$27,Parameters!$B$28),1) -> 243 | D15: =D14+C15 -> 571 | E15: =D15*Parameters!$B$29*100 -> 1142 | F15: =60/(1+D15*Parameters!$B$29*0.5) -> 8.9418778
A16: 12 | B16: =B15*3 -> 177147000000000 | C16: =FLOOR(POWER(B16/Parameters!$B$27,Parameters!$B$28),1) -> 420 | D16: =D15+C16 -> 991 | E16: =D16*Parameters!$B$29*100 -> 1982 | F16: =60/(1+D16*Parameters!$B$29*0.5) -> 5.4995417
A17: 13 | B17: =B16*3 -> 531441000000000 | C17: =FLOOR(POWER(B17/Parameters!$B$27,Parameters!$B$28),1) -> 729 | D17: =D16+C17 -> 1720 | E17: =D17*Parameters!$B$29*100 -> 3440 | F17: =60/(1+D17*Parameters!$B$29*0.5) -> 3.2967033
... A24: 20 | B24: =B23*3 -> 1.1622615e+18 | C24: =FLOOR(POWER(B24/Parameters!$B$27,Parameters!$B$28),1) -> 34091 | D24: =D23+C24 -> 80654 | E24: =D24*Parameters!$B$29*100 -> 161308 | F24: =60/(1+D24*Parameters!$B$29*0.5) -> 0.074299725
A27: SUMMARY METRICS
A28: Total IP po 20 prestiżach | B28: =D24 -> 80654
A29: Total multiplier po 20 prestiżach (%) | B29: =E24 -> 161308
A30: Total godzin do 20 prestiżu | B30: =SUM(F5:F24) -> 449.1084
A31: Średnio godzin na prestiż | B31: =AVERAGE(F5:F24) -> 22.45542
